bash-3.2$ python python_test.py 
Traceback (most recent call last):
  File "python_test.py", line 10, in <module>
    print(test["a"])
KeyError: 'a'
bash-3.2$ node javascript_test.js 
node:assert:400
    throw err;
    ^

AssertionError [ERR_ASSERTION]: The expression evaluated to a falsy value:

  assert(1 === "one")

    at assert_test (/Users/demouser/Projects/demo/javascript_test.js:4:5)
    at Object.<anonymous> (/Users/demouser/Projects/demo/javascript_test.js:7:1)
    at Module._compile (node:internal/modules/cjs/loader:1159:14)
    at Module._extensions..js (node:internal/modules/cjs/loader:1213:10)
    at Module.load (node:internal/modules/cjs/loader:1037:32)
    at Module._load (node:internal/modules/cjs/loader:878:12)
    at Function.executeUserEntryPoint [as runMain] (node:internal/modules/run_main:81:12)
    at node:internal/main/run_main_module:23:47 {
  generatedMessage: true,
  code: 'ERR_ASSERTION',
  actual: false,
  expected: true,
  operator: '=='
}

Node.js v18.12.1
(.venv) bash-3.2$ pytest tests/test_meetings.py 
==================================== test session starts =====================================
platform darwin -- Python 3.8.5, pytest-7.1.2, pluggy-1.0.0
rootdir: /Users/demouser/meetingsproject, configfile: pyproject.toml
collected 596 items                                                                          

tests/test_meetings.py F........................................................ [  9%]
...................................................................................... [ 23%]
...................................................................................... [ 38%]
...................................................................................... [ 52%]
...................................................................................... [ 67%]
...................................................................................... [ 81%]
...................................................................................... [ 96%]
.......................                                                                [100%]

========================================== FAILURES ==========================================
______________________________________ test_item_count _______________________________________

    def test_item_count():
>       assert len(parsed_items) == 3423
E       AssertionError: assert 584 == 3423
E        +  where 584 = len([{'all_day': False,\n 'classification': 'City Council',\n 'created': FakeDatetime(2022, 3, 1, 0, 0),\n 'description': '',...passed',\n 'time_notes': '',\n 'title': 'Regular City Council Meeting',\n 'updated': FakeDatetime(2022, 3, 1, 0, 0)}, ...])

tests/test_meetings.py:34: AssertionError
================================== short test summary info ===================================
FAILED tests/test_meetings.py::test_item_count - AssertionError: assert 584 == 3423
=============================== 1 failed, 595 passed in 4.92s ================================
bash-3.2$ pip search openstates 
ERROR: Exception:
Traceback (most recent call last):
  File "/Users/demouser/miniconda3/lib/python3.8/site-packages/pip/_internal/cli/base_command.py", line 228, in _main
    status = self.run(options, args)
  File "/Users/demouser/miniconda3/lib/python3.8/site-packages/pip/_internal/commands/search.py", line 60, in run
    pypi_hits = self.search(query, options)
  File "/Users/demouser/miniconda3/lib/python3.8/site-packages/pip/_internal/commands/search.py", line 80, in search
    hits = pypi.search({'name': query, 'summary': query}, 'or')
  File "/Users/demouser/miniconda3/lib/python3.8/xmlrpc/client.py", line 1109, in __call__
    return self.__send(self.__name, args)
  File "/Users/demouser/miniconda3/lib/python3.8/xmlrpc/client.py", line 1450, in __request
    response = self.__transport.request(
  File "/Users/demouser/miniconda3/lib/python3.8/site-packages/pip/_internal/network/xmlrpc.py", line 45, in request
    return self.parse_response(response.raw)
  File "/Users/demouser/miniconda3/lib/python3.8/xmlrpc/client.py", line 1341, in parse_response
    return u.close()
  File "/Users/demouser/miniconda3/lib/python3.8/xmlrpc/client.py", line 655, in close
    raise Fault(**self._stack[0])
xmlrpc.client.Fault: <Fault -32500: "RuntimeError: PyPI no longer supports 'pip search' (or XML-RPC search). Please use https://pypi.org/search (via a browser) instead. See https://warehouse.pypa.io/api-reference/xml-rpc.html#deprecated-methods for more information.">
bash-3.2$ npm i react-swipeable-views 
npm ERR! code ERESOLVE
npm ERR! ERESOLVE unable to resolve dependency tree
npm ERR! 
npm ERR! While resolving: web@0.1.0
npm ERR! Found: react@18.2.0
npm ERR! node_modules/react
npm ERR!   react@"^18.2.0" from the root project
npm ERR! 
npm ERR! Could not resolve dependency:
npm ERR! peer react@"^15.3.0 || ^16.0.0 || ^17.0.0" from react-swipeable-views@0.14.0
npm ERR! node_modules/react-swipeable-views
npm ERR!   react-swipeable-views@"*" from the root project
npm ERR! 
npm ERR! Fix the upstream dependency conflict, or retry
npm ERR! this command with --force, or --legacy-peer-deps
npm ERR! to accept an incorrect (and potentially broken) dependency resolution.
npm ERR! 
npm ERR! See /home/demouser/.npm/eresolve-report.txt for a full report.

npm ERR! A complete log of this run can be found in:
npm ERR!     /home/demouser/.npm/_logs/2022-08-04T16_50_51_600Z-debug-0.log
bash-3.2$